Workbook

Sheet Read Me
A1: Cleo Camp Style Number System
A3: THE FORMAT
A4: Style number = 2-letter category + 3-digit sequence. Example: TP101 (Cleo Tee).
A5: SKU = STYLE - COLORWAY - SIZE. Example: TP101-BLK-01 (Cleo Tee, Black, size 1).
A7: THE RULES
A8: 1. A style is a pattern/design. Change the pattern, get a new number. Change only the color or size, keep the number.
A9: 2. Numbers are never reused, even if a product is retired.
A10: 3. Season, year and status are columns, not part of the code. A Cleo Tee in SS26 is the same style as in SS25.
A11: 4. Only letters, digits and hyphens. No parentheses, spaces or slashes.
A12: 5. Colors and sizes come from the Code Tables sheet. Add a code there first, then use it.
A13: 6. Next free style in a category is shown on Code Tables. Sequence starts at 101.
A15: SHEETS
... A24: Grey cells are formulas. Don't type over them.

Sheet Styles
A1: Style | B1: Product | C1: Cat | D1: Category | E1: Status | F1: Sizes | G1: # Colorways | H1: # SKUs | I1: Notes
A2: TP101 | B2: Cleo Tee | C2: =LEFT(A2,2) -> TP | D2: =IFERROR(INDEX('Code Tables'!$B$2:$B$20,MATCH(C2,'Code Tables'!$A$2:$A$20,0)),"?") -> Tops | E2: ACTIVE | F2: 01, 02, 03 | G2: =SUMIFS(SKUs!$O$2:$O$105,SKUs!$B$2:$B$105,A2) -> 9 | H2: =COUNTIF(SKUs!$B$2:$B$105,A2) -> 27 | I2: One style, many colorways (Black, White, Blackberry, Hot Pink, Splash, Red, Shell, Splish, Sunshine). Shopify spreads these across 8 product pages.
A3: TP102 | B3: Cosmo Tee | C3: =LEFT(A3,2) -> TP | D3: =IFERROR(INDEX('Code Tables'!$B$2:$B$20,MATCH(C3,'Code Tables'!$A$2:$A$20,0)),"?") -> Tops | E3: DRAFT | F3: 01, 02, 03 | G3: =SUMIFS(SKUs!$O$2:$O$105,SKUs!$B$2:$B$105,A3) -> 1 | H3: =COUNTIF(SKUs!$B$2:$B$105,A3) -> 3 | I3: Red Stripe. Separate pattern from the Cleo Tee, so its own style.
A4: DR101 | B4: You Dress | C4: =LEFT(A4,2) -> DR | D4: =IFERROR(INDEX('Code Tables'!$B$2:$B$20,MATCH(C4,'Code Tables'!$A$2:$A$20,0)),"?") -> Dresses | E4: ACTIVE | F4: 01, 02, 03 | G4: =SUMIFS(SKUs!$O$2:$O$105,SKUs!$B$2:$B$105,A4) -> 2 | H4: =COUNTIF(SKUs!$B$2:$B$105,A4) -> 6 | I4: Black and White.
A5: DR102 | B5: Story Dress | C5: =LEFT(A5,2) -> DR | D5: =IFERROR(INDEX('Code Tables'!$B$2:$B$20,MATCH(C5,'Code Tables'!$A$2:$A$20,0)),"?") -> Dresses | E5: ACTIVE | F5: 00, 01, 02, 03 | G5: =SUMIFS(SKUs!$O$2:$O$105,SKUs!$B$2:$B$105,A5) -> 2 | H5: =COUNTIF(SKUs!$B$2:$B$105,A5) -> 8 | I5: Red (Wiltshire) and Green (Betsey).
A6: BT101 | B6: 5to7 Skirt | C6: =LEFT(A6,2) -> BT | D6: =IFERROR(INDEX('Code Tables'!$B$2:$B$20,MATCH(C6,'Code Tables'!$A$2:$A$20,0)),"?") -> Bottoms | E6: NOT LIVE | F6: XS, SM, MD, LG, XL | G6: =SUMIFS(SKUs!$O$2:$O$105,SKUs!$B$2:$B$105,A6) -> 2 | H6: =COUNTIF(SKUs!$B$2:$B$105,A6) -> 10 | I6: Product exists, not in Shopify yet. Pink and Purple assumed to be two colorways (confirm).
A7: BG101 | B7: Cleo Bag | C7: =LEFT(A7,2) -> BG | D7: =IFERROR(INDEX('Code Tables'!$B$2:$B$20,MATCH(C7,'Code Tables'!$A$2:$A$20,0)),"?") -> Bags | E7: ACTIVE | F7: OS | G7: =SUMIFS(SKUs!$O$2:$O$105,SKUs!$B$2:$B$105,A7) -> 6 | H7: =COUNTIF(SKUs!$B$2:$B$105,A7) -> 6 | I7: Chocolate, Black, Silver, Olive, Denim Baby Blue, Denim Pink. Same pattern whether Shopify shows 5 products or 1 with variants.
A8: BG102 | B8: Little Sister | C8: =LEFT(A8,2) -> BG | D8: =IFERROR(INDEX('Code Tables'!$B$2:$B$20,MATCH(C8,'Code Tables'!$A$2:$A$20,0)),"?") -> Bags | E8: ACTIVE | F8: OS | G8: =SUMIFS(SKUs!$O$2:$O$105,SKUs!$B$2:$B$105,A8) -> 1 | H8: =COUNTIF(SKUs!$B$2:$B$105,A8) -> 1 | I8: Black.
A9: BG103 | B9: Bateau Bag | C9: =LEFT(A9,2) -> BG | D9: =IFERROR(INDEX('Code Tables'!$B$2:$B$20,MATCH(C9,'Code Tables'!$A$2:$A$20,0)),"?") -> Bags | E9: ACTIVE | F9: OS | G9: =SUMIFS(SKUs!$O$2:$O$105,SKUs!$B$2:$B$105,A9) -> 6 | H9: =COUNTIF(SKUs!$B$2:$B$105,A9) -> 6 | I9: Kit: body PT101 + handle AC102 in the same color. Sold as a bundle; the handle also sold alone. Confirmed.
A10: BG104 | B10: Petite Bateau Bag | C10: =LEFT(A10,2) -> BG | D10: =IFERROR(INDEX('Code Tables'!$B$2:$B$20,MATCH(C10,'Code Tables'!$A$2:$A$20,0)),"?") -> Bags | E10: ACTIVE | F10: OS | G10: =SUMIFS(SKUs!$O$2:$O$105,SKUs!$B$2:$B$105,A10) -> 6 | H10: =COUNTIF(SKUs!$B$2:$B$105,A10) -> 6 | I10: Kit: body PT102 + handle AC102. Same handle fits both bag sizes. Confirmed.
A11: BG105 | B11: Bean Bag | C11: =LEFT(A11,2) -> BG | D11: =IFERROR(INDEX('Code Tables'!$B$2:$B$20,MATCH(C11,'Code Tables'!$A$2:$A$20,0)),"?") -> Bags | E11: ACTIVE | F11: PT, MD | G11: =SUMIFS(SKUs!$O$2:$O$105,SKUs!$B$2:$B$105,A11) -> 4 | H11: =COUNTIF(SKUs!$B$2:$B$105,A11) -> 4 | I11: Petite and Medium are sizes of one style. Confirmed. Red Petite is sold live only, not in Shopify.
A12: BG106 | B12: Cachet | C12: =LEFT(A12,2) -> BG | D12: =IFERROR(INDEX('Code Tables'!$B$2:$B$20,MATCH(C12,'Code Tables'!$A$2:$A$20,0)),"?") -> Bags | E12: ACTIVE | F12: OS | G12: =SUMIFS(SKUs!$O$2:$O$105,SKUs!$B$2:$B$105,A12) -> 1 | H12: =COUNTIF(SKUs!$B$2:$B$105,A12) -> 1 | I12: Wallet/clutch, floral and crushed gold leather.
A13: AC101 | B13: Boy Belt | C13: =LEFT(A13,2) -> AC | D13: =IFERROR(INDEX('Code Tables'!$B$2:$B$20,MATCH(C13,'Code Tables'!$A$2:$A$20,0)),"?") -> Accessories | E13: ACTIVE | F13: XS, SM, MD, LG | G13: =SUMIFS(SKUs!$O$2:$O$105,SKUs!$B$2:$B$105,A13) -> 1 | H13: =COUNTIF(SKUs!$B$2:$B$105,A13) -> 4 | I13: Dark chocolate leather, silver buckle.
... A27: BT102 | B27: Tutu | C27: =LEFT(A27,2) -> BT | D27: =IFERROR(INDEX('Code Tables'!$B$2:$B$20,MATCH(C27,'Code Tables'!$A$2:$A$20,0)),"?") -> Bottoms | E27: PROPOSED | F27: TBD | G27: =SUMIFS(SKUs!$O$2:$O$105,SKUs!$B$2:$B$105,A27) -> 0 | H27: =COUNTIF(SKUs!$B$2:$B$105,A27) -> 0 | I27: Sampling. Number proposed, not confirmed.
A28: Total | G28: =SUM(G2:G27) -> 55 | H28: =SUM(H2:H27) -> 104

Sheet SKUs
A1: SKU (new) | B1: Style | C1: Product | D1: Color | E1: Colorway | F1: Size | G1: Size name | H1: Shopify handle | I1: Variant title | J1: Old SKU | K1: Status | L1: Season | M1: Check | N1: Notes | O1: Colorway count
A2: =B2&"-"&D2&"-"&F2 -> TP101-BLK-01 | B2: TP101 | C2: =IFERROR(INDEX(Styles!$B$2:$B$27,MATCH(B2,Styles!$A$2:$A$27,0)),"?") -> Cleo Tee | D2: BLK | E2: =IFERROR(INDEX('Code Tables'!$E$2:$E$40,MATCH(D2,'Code Tables'!$D$2:$D$40,0)),"?") -> Black | F2: 01 | G2: =IFERROR(INDEX('Code Tables'!$J$2:$J$20,MATCH(F2,'Code Tables'!$I$2:$I$20,0)),"?") -> Size 1 | H2: cleo-tee-w | I2: Black / 1 | J2: CCSS25COT-BLK01 | K2: ACTIVE | L2: SS25 | M2: =IF(COUNTIF($A$2:$A$105,A2)>1,"DUPLICATE",IF(ISNA(MATCH(B2,Styles!$A$2:$A$27,0)),"BAD STYLE",IF(ISNA(MATCH(D2,'Code Tables'!$D$2:$D$40,0)),"BAD COLOR",IF(ISNA(MATCH(F2,'Code Tables'!$I$2:$I$20,0)),"BAD SIZE","ok")))) -> ok | O2: =IF(COUNTIFS($B$2:B2,B2,$D$2:D2,D2)=1,1,0) -> 1
A3: =B3&"-"&D3&"-"&F3 -> TP101-BLK-02 | B3: TP101 | C3: =IFERROR(INDEX(Styles!$B$2:$B$27,MATCH(B3,Styles!$A$2:$A$27,0)),"?") -> Cleo Tee | D3: BLK | E3: =IFERROR(INDEX('Code Tables'!$E$2:$E$40,MATCH(D3,'Code Tables'!$D$2:$D$40,0)),"?") -> Black | F3: 02 | G3: =IFERROR(INDEX('Code Tables'!$J$2:$J$20,MATCH(F3,'Code Tables'!$I$2:$I$20,0)),"?") -> Size 2 | H3: cleo-tee-w | I3: Black / 2 | J3: CCSS25COT-BLK02 | K3: ACTIVE | L3: SS25 | M3: =IF(COUNTIF($A$2:$A$105,A3)>1,"DUPLICATE",IF(ISNA(MATCH(B3,Styles!$A$2:$A$27,0)),"BAD STYLE",IF(ISNA(MATCH(D3,'Code Tables'!$D$2:$D$40,0)),"BAD COLOR",IF(ISNA(MATCH(F3,'Code Tables'!$I$2:$I$20,0)),"BAD SIZE","ok")))) -> ok | O3: =IF(COUNTIFS($B$2:B3,B3,$D$2:D3,D3)=1,1,0) -> 0
A4: =B4&"-"&D4&"-"&F4 -> TP101-BLK-03 | B4: TP101 | C4: =IFERROR(INDEX(Styles!$B$2:$B$27,MATCH(B4,Styles!$A$2:$A$27,0)),"?") -> Cleo Tee | D4: BLK | E4: =IFERROR(INDEX('Code Tables'!$E$2:$E$40,MATCH(D4,'Code Tables'!$D$2:$D$40,0)),"?") -> Black | F4: 03 | G4: =IFERROR(INDEX('Code Tables'!$J$2:$J$20,MATCH(F4,'Code Tables'!$I$2:$I$20,0)),"?") -> Size 3 | H4: cleo-tee-w | I4: Black / 3 | J4: CCSS25COT-BLK03 | K4: ACTIVE | L4: SS25 | M4: =IF(COUNTIF($A$2:$A$105,A4)>1,"DUPLICATE",IF(ISNA(MATCH(B4,Styles!$A$2:$A$27,0)),"BAD STYLE",IF(ISNA(MATCH(D4,'Code Tables'!$D$2:$D$40,0)),"BAD COLOR",IF(ISNA(MATCH(F4,'Code Tables'!$I$2:$I$20,0)),"BAD SIZE","ok")))) -> ok | O4: =IF(COUNTIFS($B$2:B4,B4,$D$2:D4,D4)=1,1,0) -> 0
A5: =B5&"-"&D5&"-"&F5 -> TP101-WHT-01 | B5: TP101 | C5: =IFERROR(INDEX(Styles!$B$2:$B$27,MATCH(B5,Styles!$A$2:$A$27,0)),"?") -> Cleo Tee | D5: WHT | E5: =IFERROR(INDEX('Code Tables'!$E$2:$E$40,MATCH(D5,'Code Tables'!$D$2:$D$40,0)),"?") -> White | F5: 01 | G5: =IFERROR(INDEX('Code Tables'!$J$2:$J$20,MATCH(F5,'Code Tables'!$I$2:$I$20,0)),"?") -> Size 1 | H5: cleo-tee-w | I5: White / 1 | J5: CCSS25COT-WHT01 | K5: ACTIVE | L5: SS25 | M5: =IF(COUNTIF($A$2:$A$105,A5)>1,"DUPLICATE",IF(ISNA(MATCH(B5,Styles!$A$2:$A$27,0)),"BAD STYLE",IF(ISNA(MATCH(D5,'Code Tables'!$D$2:$D$40,0)),"BAD COLOR",IF(ISNA(MATCH(F5,'Code Tables'!$I$2:$I$20,0)),"BAD SIZE","ok")))) -> ok | O5: =IF(COUNTIFS($B$2:B5,B5,$D$2:D5,D5)=1,1,0) -> 1
A6: =B6&"-"&D6&"-"&F6 -> TP101-WHT-02 | B6: TP101 | C6: =IFERROR(INDEX(Styles!$B$2:$B$27,MATCH(B6,Styles!$A$2:$A$27,0)),"?") -> Cleo Tee | D6: WHT | E6: =IFERROR(INDEX('Code Tables'!$E$2:$E$40,MATCH(D6,'Code Tables'!$D$2:$D$40,0)),"?") -> White | F6: 02 | G6: =IFERROR(INDEX('Code Tables'!$J$2:$J$20,MATCH(F6,'Code Tables'!$I$2:$I$20,0)),"?") -> Size 2 | H6: cleo-tee-w | I6: White / 2 | J6: CCSS25COT-WHT02 | K6: ACTIVE | L6: SS25 | M6: =IF(COUNTIF($A$2:$A$105,A6)>1,"DUPLICATE",IF(ISNA(MATCH(B6,Styles!$A$2:$A$27,0)),"BAD STYLE",IF(ISNA(MATCH(D6,'Code Tables'!$D$2:$D$40,0)),"BAD COLOR",IF(ISNA(MATCH(F6,'Code Tables'!$I$2:$I$20,0)),"BAD SIZE","ok")))) -> ok | O6: =IF(COUNTIFS($B$2:B6,B6,$D$2:D6,D6)=1,1,0) -> 0
A7: =B7&"-"&D7&"-"&F7 -> TP101-WHT-03 | B7: TP101 | C7: =IFERROR(INDEX(Styles!$B$2:$B$27,MATCH(B7,Styles!$A$2:$A$27,0)),"?") -> Cleo Tee | D7: WHT | E7: =IFERROR(INDEX('Code Tables'!$E$2:$E$40,MATCH(D7,'Code Tables'!$D$2:$D$40,0)),"?") -> White | F7: 03 | G7: =IFERROR(INDEX('Code Tables'!$J$2:$J$20,MATCH(F7,'Code Tables'!$I$2:$I$20,0)),"?") -> Size 3 | H7: cleo-tee-w | I7: White / 3 | J7: CCSS25COT-WHT03 | K7: ACTIVE | L7: SS25 | M7: =IF(COUNTIF($A$2:$A$105,A7)>1,"DUPLICATE",IF(ISNA(MATCH(B7,Styles!$A$2:$A$27,0)),"BAD STYLE",IF(ISNA(MATCH(D7,'Code Tables'!$D$2:$D$40,0)),"BAD COLOR",IF(ISNA(MATCH(F7,'Code Tables'!$I$2:$I$20,0)),"BAD SIZE","ok")))) -> ok | O7: =IF(COUNTIFS($B$2:B7,B7,$D$2:D7,D7)=1,1,0) -> 0
A8: =B8&"-"&D8&"-"&F8 -> TP101-BER-01 | B8: TP101 | C8: =IFERROR(INDEX(Styles!$B$2:$B$27,MATCH(B8,Styles!$A$2:$A$27,0)),"?") -> Cleo Tee | D8: BER | E8: =IFERROR(INDEX('Code Tables'!$E$2:$E$40,MATCH(D8,'Code Tables'!$D$2:$D$40,0)),"?") -> Blackberry | F8: 01 | G8: =IFERROR(INDEX('Code Tables'!$J$2:$J$20,MATCH(F8,'Code Tables'!$I$2:$I$20,0)),"?") -> Size 1 | H8: cleo-tee-blackberry | I8: Blackberry / 1 | J8: CCSS26COT-BER01 | K8: UNLISTED | L8: SS26 | M8: =IF(COUNTIF($A$2:$A$105,A8)>1,"DUPLICATE",IF(ISNA(MATCH(B8,Styles!$A$2:$A$27,0)),"BAD STYLE",IF(ISNA(MATCH(D8,'Code Tables'!$D$2:$D$40,0)),"BAD COLOR",IF(ISNA(MATCH(F8,'Code Tables'!$I$2:$I$20,0)),"BAD SIZE","ok")))) -> ok | O8: =IF(COUNTIFS($B$2:B8,B8,$D$2:D8,D8)=1,1,0) -> 1
A9: =B9&"-"&D9&"-"&F9 -> TP101-BER-02 | B9: TP101 | C9: =IFERROR(INDEX(Styles!$B$2:$B$27,MATCH(B9,Styles!$A$2:$A$27,0)),"?") -> Cleo Tee | D9: BER | E9: =IFERROR(INDEX('Code Tables'!$E$2:$E$40,MATCH(D9,'Code Tables'!$D$2:$D$40,0)),"?") -> Blackberry | F9: 02 | G9: =IFERROR(INDEX('Code Tables'!$J$2:$J$20,MATCH(F9,'Code Tables'!$I$2:$I$20,0)),"?") -> Size 2 | H9: cleo-tee-blackberry | I9: Blackberry / 2 | J9: CCSS26COT-BER02 | K9: UNLISTED | L9: SS26 | M9: =IF(COUNTIF($A$2:$A$105,A9)>1,"DUPLICATE",IF(ISNA(MATCH(B9,Styles!$A$2:$A$27,0)),"BAD STYLE",IF(ISNA(MATCH(D9,'Code Tables'!$D$2:$D$40,0)),"BAD COLOR",IF(ISNA(MATCH(F9,'Code Tables'!$I$2:$I$20,0)),"BAD SIZE","ok")))) -> ok | O9: =IF(COUNTIFS($B$2:B9,B9,$D$2:D9,D9)=1,1,0) -> 0
A10: =B10&"-"&D10&"-"&F10 -> TP101-BER-03 | B10: TP101 | C10: =IFERROR(INDEX(Styles!$B$2:$B$27,MATCH(B10,Styles!$A$2:$A$27,0)),"?") -> Cleo Tee | D10: BER | E10: =IFERROR(INDEX('Code Tables'!$E$2:$E$40,MATCH(D10,'Code Tables'!$D$2:$D$40,0)),"?") -> Blackberry | F10: 03 | G10: =IFERROR(INDEX('Code Tables'!$J$2:$J$20,MATCH(F10,'Code Tables'!$I$2:$I$20,0)),"?") -> Size 3 | H10: cleo-tee-blackberry | I10: Blackberry / 3 | J10: CCSS26COT-BER03 | K10: UNLISTED | L10: SS26 | M10: =IF(COUNTIF($A$2:$A$105,A10)>1,"DUPLICATE",IF(ISNA(MATCH(B10,Styles!$A$2:$A$27,0)),"BAD STYLE",IF(ISNA(MATCH(D10,'Code Tables'!$D$2:$D$40,0)),"BAD COLOR",IF(ISNA(MATCH(F10,'Code Tables'!$I$2:$I$20,0)),"BAD SIZE","ok")))) -> ok | O10: =IF(COUNTIFS($B$2:B10,B10,$D$2:D10,D10)=1,1,0) -> 0
A11: =B11&"-"&D11&"-"&F11 -> TP101-HPK-01 | B11: TP101 | C11: =IFERROR(INDEX(Styles!$B$2:$B$27,MATCH(B11,Styles!$A$2:$A$27,0)),"?") -> Cleo Tee | D11: HPK | E11: =IFERROR(INDEX('Code Tables'!$E$2:$E$40,MATCH(D11,'Code Tables'!$D$2:$D$40,0)),"?") -> Hot Pink | F11: 01 | G11: =IFERROR(INDEX('Code Tables'!$J$2:$J$20,MATCH(F11,'Code Tables'!$I$2:$I$20,0)),"?") -> Size 1 | H11: cleo-tee-hot-pink | I11: Hot Pink / 1 | K11: ACTIVE | M11: =IF(COUNTIF($A$2:$A$105,A11)>1,"DUPLICATE",IF(ISNA(MATCH(B11,Styles!$A$2:$A$27,0)),"BAD STYLE",IF(ISNA(MATCH(D11,'Code Tables'!$D$2:$D$40,0)),"BAD COLOR",IF(ISNA(MATCH(F11,'Code Tables'!$I$2:$I$20,0)),"BAD SIZE","ok")))) -> ok | O11: =IF(COUNTIFS($B$2:B11,B11,$D$2:D11,D11)=1,1,0) -> 1
A12: =B12&"-"&D12&"-"&F12 -> TP101-HPK-02 | B12: TP101 | C12: =IFERROR(INDEX(Styles!$B$2:$B$27,MATCH(B12,Styles!$A$2:$A$27,0)),"?") -> Cleo Tee | D12: HPK | E12: =IFERROR(INDEX('Code Tables'!$E$2:$E$40,MATCH(D12,'Code Tables'!$D$2:$D$40,0)),"?") -> Hot Pink | F12: 02 | G12: =IFERROR(INDEX('Code Tables'!$J$2:$J$20,MATCH(F12,'Code Tables'!$I$2:$I$20,0)),"?") -> Size 2 | H12: cleo-tee-hot-pink | I12: Hot Pink / 2 | K12: ACTIVE | M12: =IF(COUNTIF($A$2:$A$105,A12)>1,"DUPLICATE",IF(ISNA(MATCH(B12,Styles!$A$2:$A$27,0)),"BAD STYLE",IF(ISNA(MATCH(D12,'Code Tables'!$D$2:$D$40,0)),"BAD COLOR",IF(ISNA(MATCH(F12,'Code Tables'!$I$2:$I$20,0)),"BAD SIZE","ok")))) -> ok | O12: =IF(COUNTIFS($B$2:B12,B12,$D$2:D12,D12)=1,1,0) -> 0
A13: =B13&"-"&D13&"-"&F13 -> TP101-HPK-03 | B13: TP101 | C13: =IFERROR(INDEX(Styles!$B$2:$B$27,MATCH(B13,Styles!$A$2:$A$27,0)),"?") -> Cleo Tee | D13: HPK | E13: =IFERROR(INDEX('Code Tables'!$E$2:$E$40,MATCH(D13,'Code Tables'!$D$2:$D$40,0)),"?") -> Hot Pink | F13: 03 | G13: =IFERROR(INDEX('Code Tables'!$J$2:$J$20,MATCH(F13,'Code Tables'!$I$2:$I$20,0)),"?") -> Size 3 | H13: cleo-tee-hot-pink | I13: Hot Pink / 3 | K13: ACTIVE | M13: =IF(COUNTIF($A$2:$A$105,A13)>1,"DUPLICATE",IF(ISNA(MATCH(B13,Styles!$A$2:$A$27,0)),"BAD STYLE",IF(ISNA(MATCH(D13,'Code Tables'!$D$2:$D$40,0)),"BAD COLOR",IF(ISNA(MATCH(F13,'Code Tables'!$I$2:$I$20,0)),"BAD SIZE","ok")))) -> ok | O13: =IF(COUNTIFS($B$2:B13,B13,$D$2:D13,D13)=1,1,0) -> 0
A14: =B14&"-"&D14&"-"&F14 -> TP101-SPS-01 | B14: TP101 | C14: =IFERROR(INDEX(Styles!$B$2:$B$27,MATCH(B14,Styles!$A$2:$A$27,0)),"?") -> Cleo Tee | D14: SPS | E14: =IFERROR(INDEX('Code Tables'!$E$2:$E$40,MATCH(D14,'Code Tables'!$D$2:$D$40,0)),"?") -> Splash | F14: 01 | G14: =IFERROR(INDEX('Code Tables'!$J$2:$J$20,MATCH(F14,'Code Tables'!$I$2:$I$20,0)),"?") -> Size 1 | H14: neverworns-tee | I14: Splash / 1 | J14: CCFW25COTNV-SLPS01 | K14: ACTIVE | L14: FW25 | M14: =IF(COUNTIF($A$2:$A$105,A14)>1,"DUPLICATE",IF(ISNA(MATCH(B14,Styles!$A$2:$A$27,0)),"BAD STYLE",IF(ISNA(MATCH(D14,'Code Tables'!$D$2:$D$40,0)),"BAD COLOR",IF(ISNA(MATCH(F14,'Code Tables'!$I$2:$I$20,0)),"BAD SIZE","ok")))) -> ok | O14: =IF(COUNTIFS($B$2:B14,B14,$D$2:D14,D14)=1,1,0) -> 1
A15: =B15&"-"&D15&"-"&F15 -> TP101-SPS-02 | B15: TP101 | C15: =IFERROR(INDEX(Styles!$B$2:$B$27,MATCH(B15,Styles!$A$2:$A$27,0)),"?") -> Cleo Tee | D15: SPS | E15: =IFERROR(INDEX('Code Tables'!$E$2:$E$40,MATCH(D15,'Code Tables'!$D$2:$D$40,0)),"?") -> Splash | F15: 02 | G15: =IFERROR(INDEX('Code Tables'!$J$2:$J$20,MATCH(F15,'Code Tables'!$I$2:$I$20,0)),"?") -> Size 2 | H15: neverworns-tee | I15: Splash / 2 | J15: CCFW25COTNV-SLPS02 | K15: ACTIVE | L15: FW25 | M15: =IF(COUNTIF($A$2:$A$105,A15)>1,"DUPLICATE",IF(ISNA(MATCH(B15,Styles!$A$2:$A$27,0)),"BAD STYLE",IF(ISNA(MATCH(D15,'Code Tables'!$D$2:$D$40,0)),"BAD COLOR",IF(ISNA(MATCH(F15,'Code Tables'!$I$2:$I$20,0)),"BAD SIZE","ok")))) -> ok | O15: =IF(COUNTIFS($B$2:B15,B15,$D$2:D15,D15)=1,1,0) -> 0
A16: =B16&"-"&D16&"-"&F16 -> TP101-SPS-03 | B16: TP101 | C16: =IFERROR(INDEX(Styles!$B$2:$B$27,MATCH(B16,Styles!$A$2:$A$27,0)),"?") -> Cleo Tee | D16: SPS | E16: =IFERROR(INDEX('Code Tables'!$E$2:$E$40,MATCH(D16,'Code Tables'!$D$2:$D$40,0)),"?") -> Splash | F16: 03 | G16: =IFERROR(INDEX('Code Tables'!$J$2:$J$20,MATCH(F16,'Code Tables'!$I$2:$I$20,0)),"?") -> Size 3 | H16: neverworns-tee | I16: Splash / 3 | J16: CCFW25COTNV-SLPS03 | K16: ACTIVE | L16: FW25 | M16: =IF(COUNTIF($A$2:$A$105,A16)>1,"DUPLICATE",IF(ISNA(MATCH(B16,Styles!$A$2:$A$27,0)),"BAD STYLE",IF(ISNA(MATCH(D16,'Code Tables'!$D$2:$D$40,0)),"BAD COLOR",IF(ISNA(MATCH(F16,'Code Tables'!$I$2:$I$20,0)),"BAD SIZE","ok")))) -> ok | O16: =IF(COUNTIFS($B$2:B16,B16,$D$2:D16,D16)=1,1,0) -> 0
A17: =B17&"-"&D17&"-"&F17 -> TP101-RED-01 | B17: TP101 | C17: =IFERROR(INDEX(Styles!$B$2:$B$27,MATCH(B17,Styles!$A$2:$A$27,0)),"?") -> Cleo Tee | D17: RED | E17: =IFERROR(INDEX('Code Tables'!$E$2:$E$40,MATCH(D17,'Code Tables'!$D$2:$D$40,0)),"?") -> Red | F17: 01 | G17: =IFERROR(INDEX('Code Tables'!$J$2:$J$20,MATCH(F17,'Code Tables'!$I$2:$I$20,0)),"?") -> Size 1 | H17: ruby-red-tee | I17: Red / 1 | J17: CCFW25COT-RED01 | K17: UNLISTED | L17: FW25 | M17: =IF(COUNTIF($A$2:$A$105,A17)>1,"DUPLICATE",IF(ISNA(MATCH(B17,Styles!$A$2:$A$27,0)),"BAD STYLE",IF(ISNA(MATCH(D17,'Code Tables'!$D$2:$D$40,0)),"BAD COLOR",IF(ISNA(MATCH(F17,'Code Tables'!$I$2:$I$20,0)),"BAD SIZE","ok")))) -> ok | O17: =IF(COUNTIFS($B$2:B17,B17,$D$2:D17,D17)=1,1,0) -> 1
A18: =B18&"-"&D18&"-"&F18 -> TP101-RED-02 | B18: TP101 | C18: =IFERROR(INDEX(Styles!$B$2:$B$27,MATCH(B18,Styles!$A$2:$A$27,0)),"?") -> Cleo Tee | D18: RED | E18: =IFERROR(INDEX('Code Tables'!$E$2:$E$40,MATCH(D18,'Code Tables'!$D$2:$D$40,0)),"?") -> Red | F18: 02 | G18: =IFERROR(INDEX('Code Tables'!$J$2:$J$20,MATCH(F18,'Code Tables'!$I$2:$I$20,0)),"?") -> Size 2 | H18: ruby-red-tee | I18: Red / 2 | J18: CCFW25COT-RED02 | K18: UNLISTED | L18: FW25 | M18: =IF(COUNTIF($A$2:$A$105,A18)>1,"DUPLICATE",IF(ISNA(MATCH(B18,Styles!$A$2:$A$27,0)),"BAD STYLE",IF(ISNA(MATCH(D18,'Code Tables'!$D$2:$D$40,0)),"BAD COLOR",IF(ISNA(MATCH(F18,'Code Tables'!$I$2:$I$20,0)),"BAD SIZE","ok")))) -> ok | O18: =IF(COUNTIFS($B$2:B18,B18,$D$2:D18,D18)=1,1,0) -> 0
A19: =B19&"-"&D19&"-"&F19 -> TP101-RED-03 | B19: TP101 | C19: =IFERROR(INDEX(Styles!$B$2:$B$27,MATCH(B19,Styles!$A$2:$A$27,0)),"?") -> Cleo Tee | D19: RED | E19: =IFERROR(INDEX('Code Tables'!$E$2:$E$40,MATCH(D19,'Code Tables'!$D$2:$D$40,0)),"?") -> Red | F19: 03 | G19: =IFERROR(INDEX('Code Tables'!$J$2:$J$20,MATCH(F19,'Code Tables'!$I$2:$I$20,0)),"?") -> Size 3 | H19: ruby-red-tee | I19: Red / 3 | J19: CCFW25COT-RED03 | K19: UNLISTED | L19: FW25 | M19: =IF(COUNTIF($A$2:$A$105,A19)>1,"DUPLICATE",IF(ISNA(MATCH(B19,Styles!$A$2:$A$27,0)),"BAD STYLE",IF(ISNA(MATCH(D19,'Code Tables'!$D$2:$D$40,0)),"BAD COLOR",IF(ISNA(MATCH(F19,'Code Tables'!$I$2:$I$20,0)),"BAD SIZE","ok")))) -> ok | O19: =IF(COUNTIFS($B$2:B19,B19,$D$2:D19,D19)=1,1,0) -> 0
A20: =B20&"-"&D20&"-"&F20 -> TP101-SHL-01 | B20: TP101 | C20: =IFERROR(INDEX(Styles!$B$2:$B$27,MATCH(B20,Styles!$A$2:$A$27,0)),"?") -> Cleo Tee | D20: SHL | E20: =IFERROR(INDEX('Code Tables'!$E$2:$E$40,MATCH(D20,'Code Tables'!$D$2:$D$40,0)),"?") -> Shell | F20: 01 | G20: =IFERROR(INDEX('Code Tables'!$J$2:$J$20,MATCH(F20,'Code Tables'!$I$2:$I$20,0)),"?") -> Size 1 | H20: cleo-tee-shell | I20: Shell / 1 | J20: CCSS26COT-SHL01 | K20: ACTIVE | L20: SS26 | M20: =IF(COUNTIF($A$2:$A$105,A20)>1,"DUPLICATE",IF(ISNA(MATCH(B20,Styles!$A$2:$A$27,0)),"BAD STYLE",IF(ISNA(MATCH(D20,'Code Tables'!$D$2:$D$40,0)),"BAD COLOR",IF(ISNA(MATCH(F20,'Code Tables'!$I$2:$I$20,0)),"BAD SIZE","ok")))) -> ok | O20: =IF(COUNTIFS($B$2:B20,B20,$D$2:D20,D20)=1,1,0) -> 1
A21: =B21&"-"&D21&"-"&F21 -> TP101-SHL-02 | B21: TP101 | C21: =IFERROR(INDEX(Styles!$B$2:$B$27,MATCH(B21,Styles!$A$2:$A$27,0)),"?") -> Cleo Tee | D21: SHL | E21: =IFERROR(INDEX('Code Tables'!$E$2:$E$40,MATCH(D21,'Code Tables'!$D$2:$D$40,0)),"?") -> Shell | F21: 02 | G21: =IFERROR(INDEX('Code Tables'!$J$2:$J$20,MATCH(F21,'Code Tables'!$I$2:$I$20,0)),"?") -> Size 2 | H21: cleo-tee-shell | I21: Shell / 2 | J21: CCSS26COT-SHL02 | K21: ACTIVE | L21: SS26 | M21: =IF(COUNTIF($A$2:$A$105,A21)>1,"DUPLICATE",IF(ISNA(MATCH(B21,Styles!$A$2:$A$27,0)),"BAD STYLE",IF(ISNA(MATCH(D21,'Code Tables'!$D$2:$D$40,0)),"BAD COLOR",IF(ISNA(MATCH(F21,'Code Tables'!$I$2:$I$20,0)),"BAD SIZE","ok")))) -> ok | O21: =IF(COUNTIFS($B$2:B21,B21,$D$2:D21,D21)=1,1,0) -> 0
A22: =B22&"-"&D22&"-"&F22 -> TP101-SHL-03 | B22: TP101 | C22: =IFERROR(INDEX(Styles!$B$2:$B$27,MATCH(B22,Styles!$A$2:$A$27,0)),"?") -> Cleo Tee | D22: SHL | E22: =IFERROR(INDEX('Code Tables'!$E$2:$E$40,MATCH(D22,'Code Tables'!$D$2:$D$40,0)),"?") -> Shell | F22: 03 | G22: =IFERROR(INDEX('Code Tables'!$J$2:$J$20,MATCH(F22,'Code Tables'!$I$2:$I$20,0)),"?") -> Size 3 | H22: cleo-tee-shell | I22: Shell / 3 | J22: CCSS26COT-SHL03 | K22: ACTIVE | L22: SS26 | M22: =IF(COUNTIF($A$2:$A$105,A22)>1,"DUPLICATE",IF(ISNA(MATCH(B22,Styles!$A$2:$A$27,0)),"BAD STYLE",IF(ISNA(MATCH(D22,'Code Tables'!$D$2:$D$40,0)),"BAD COLOR",IF(ISNA(MATCH(F22,'Code Tables'!$I$2:$I$20,0)),"BAD SIZE","ok")))) -> ok | O22: =IF(COUNTIFS($B$2:B22,B22,$D$2:D22,D22)=1,1,0) -> 0
A23: =B23&"-"&D23&"-"&F23 -> TP101-SPL-01 | B23: TP101 | C23: =IFERROR(INDEX(Styles!$B$2:$B$27,MATCH(B23,Styles!$A$2:$A$27,0)),"?") -> Cleo Tee | D23: SPL | E23: =IFERROR(INDEX('Code Tables'!$E$2:$E$40,MATCH(D23,'Code Tables'!$D$2:$D$40,0)),"?") -> Splish | F23: 01 | G23: =IFERROR(INDEX('Code Tables'!$J$2:$J$20,MATCH(F23,'Code Tables'!$I$2:$I$20,0)),"?") -> Size 1 | H23: cleo-tee-splish | I23: Splish / 1 | K23: ACTIVE | M23: =IF(COUNTIF($A$2:$A$105,A23)>1,"DUPLICATE",IF(ISNA(MATCH(B23,Styles!$A$2:$A$27,0)),"BAD STYLE",IF(ISNA(MATCH(D23,'Code Tables'!$D$2:$D$40,0)),"BAD COLOR",IF(ISNA(MATCH(F23,'Code Tables'!$I$2:$I$20,0)),"BAD SIZE","ok")))) -> ok | O23: =IF(COUNTIFS($B$2:B23,B23,$D$2:D23,D23)=1,1,0) -> 1
A24: =B24&"-"&D24&"-"&F24 -> TP101-SPL-02 | B24: TP101 | C24: =IFERROR(INDEX(Styles!$B$2:$B$27,MATCH(B24,Styles!$A$2:$A$27,0)),"?") -> Cleo Tee | D24: SPL | E24: =IFERROR(INDEX('Code Tables'!$E$2:$E$40,MATCH(D24,'Code Tables'!$D$2:$D$40,0)),"?") -> Splish | F24: 02 | G24: =IFERROR(INDEX('Code Tables'!$J$2:$J$20,MATCH(F24,'Code Tables'!$I$2:$I$20,0)),"?") -> Size 2 | H24: cleo-tee-splish | I24: Splish / 2 | K24: ACTIVE | M24: =IF(COUNTIF($A$2:$A$105,A24)>1,"DUPLICATE",IF(ISNA(MATCH(B24,Styles!$A$2:$A$27,0)),"BAD STYLE",IF(ISNA(MATCH(D24,'Code Tables'!$D$2:$D$40,0)),"BAD COLOR",IF(ISNA(MATCH(F24,'Code Tables'!$I$2:$I$20,0)),"BAD SIZE","ok")))) -> ok | O24: =IF(COUNTIFS($B$2:B24,B24,$D$2:D24,D24)=1,1,0) -> 0
A25: =B25&"-"&D25&"-"&F25 -> TP101-SPL-03 | B25: TP101 | C25: =IFERROR(INDEX(Styles!$B$2:$B$27,MATCH(B25,Styles!$A$2:$A$27,0)),"?") -> Cleo Tee | D25: SPL | E25: =IFERROR(INDEX('Code Tables'!$E$2:$E$40,MATCH(D25,'Code Tables'!$D$2:$D$40,0)),"?") -> Splish | F25: 03 | G25: =IFERROR(INDEX('Code Tables'!$J$2:$J$20,MATCH(F25,'Code Tables'!$I$2:$I$20,0)),"?") -> Size 3 | H25: cleo-tee-splish | I25: Splish / 3 | K25: ACTIVE | M25: =IF(COUNTIF($A$2:$A$105,A25)>1,"DUPLICATE",IF(ISNA(MATCH(B25,Styles!$A$2:$A$27,0)),"BAD STYLE",IF(ISNA(MATCH(D25,'Code Tables'!$D$2:$D$40,0)),"BAD COLOR",IF(ISNA(MATCH(F25,'Code Tables'!$I$2:$I$20,0)),"BAD SIZE","ok")))) -> ok | O25: =IF(COUNTIFS($B$2:B25,B25,$D$2:D25,D25)=1,1,0) -> 0
A26: =B26&"-"&D26&"-"&F26 -> TP101-SNS-01 | B26: TP101 | C26: =IFERROR(INDEX(Styles!$B$2:$B$27,MATCH(B26,Styles!$A$2:$A$27,0)),"?") -> Cleo Tee | D26: SNS | E26: =IFERROR(INDEX('Code Tables'!$E$2:$E$40,MATCH(D26,'Code Tables'!$D$2:$D$40,0)),"?") -> Sunshine | F26: 01 | G26: =IFERROR(INDEX('Code Tables'!$J$2:$J$20,MATCH(F26,'Code Tables'!$I$2:$I$20,0)),"?") -> Size 1 | H26: cleo-tee-wheat | I26: Sunshine / 1 | J26: CCSS26COT-SNS01 | K26: ACTIVE | L26: SS26 | M26: =IF(COUNTIF($A$2:$A$105,A26)>1,"DUPLICATE",IF(ISNA(MATCH(B26,Styles!$A$2:$A$27,0)),"BAD STYLE",IF(ISNA(MATCH(D26,'Code Tables'!$D$2:$D$40,0)),"BAD COLOR",IF(ISNA(MATCH(F26,'Code Tables'!$I$2:$I$20,0)),"BAD SIZE","ok")))) -> ok | O26: =IF(COUNTIFS($B$2:B26,B26,$D$2:D26,D26)=1,1,0) -> 1
A27: =B27&"-"&D27&"-"&F27 -> TP101-SNS-02 | B27: TP101 | C27: =IFERROR(INDEX(Styles!$B$2:$B$27,MATCH(B27,Styles!$A$2:$A$27,0)),"?") -> Cleo Tee | D27: SNS | E27: =IFERROR(INDEX('Code Tables'!$E$2:$E$40,MATCH(D27,'Code Tables'!$D$2:$D$40,0)),"?") -> Sunshine | F27: 02 | G27: =IFERROR(INDEX('Code Tables'!$J$2:$J$20,MATCH(F27,'Code Tables'!$I$2:$I$20,0)),"?") -> Size 2 | H27: cleo-tee-wheat | I27: Sunshine / 2 | J27: CCSS26COT-SNS02 | K27: ACTIVE | L27: SS26 | M27: =IF(COUNTIF($A$2:$A$105,A27)>1,"DUPLICATE",IF(ISNA(MATCH(B27,Styles!$A$2:$A$27,0)),"BAD STYLE",IF(ISNA(MATCH(D27,'Code Tables'!$D$2:$D$40,0)),"BAD COLOR",IF(ISNA(MATCH(F27,'Code Tables'!$I$2:$I$20,0)),"BAD SIZE","ok")))) -> ok | O27: =IF(COUNTIFS($B$2:B27,B27,$D$2:D27,D27)=1,1,0) -> 0
A28: =B28&"-"&D28&"-"&F28 -> TP101-SNS-03 | B28: TP101 | C28: =IFERROR(INDEX(Styles!$B$2:$B$27,MATCH(B28,Styles!$A$2:$A$27,0)),"?") -> Cleo Tee | D28: SNS | E28: =IFERROR(INDEX('Code Tables'!$E$2:$E$40,MATCH(D28,'Code Tables'!$D$2:$D$40,0)),"?") -> Sunshine | F28: 03 | G28: =IFERROR(INDEX('Code Tables'!$J$2:$J$20,MATCH(F28,'Code Tables'!$I$2:$I$20,0)),"?") -> Size 3 | H28: cleo-tee-wheat | I28: Sunshine / 3 | J28: CCSS26COT-SNS03 | K28: ACTIVE | L28: SS26 | M28: =IF(COUNTIF($A$2:$A$105,A28)>1,"DUPLICATE",IF(ISNA(MATCH(B28,Styles!$A$2:$A$27,0)),"BAD STYLE",IF(ISNA(MATCH(D28,'Code Tables'!$D$2:$D$40,0)),"BAD COLOR",IF(ISNA(MATCH(F28,'Code Tables'!$I$2:$I$20,0)),"BAD SIZE","ok")))) -> ok | O28: =IF(COUNTIFS($B$2:B28,B28,$D$2:D28,D28)=1,1,0) -> 0
A29: =B29&"-"&D29&"-"&F29 -> TP102-RST-01 | B29: TP102 | C29: =IFERROR(INDEX(Styles!$B$2:$B$27,MATCH(B29,Styles!$A$2:$A$27,0)),"?") -> Cosmo Tee | D29: RST | E29: =IFERROR(INDEX('Code Tables'!$E$2:$E$40,MATCH(D29,'Code Tables'!$D$2:$D$40,0)),"?") -> Red Stripe | F29: 01 | G29: =IFERROR(INDEX('Code Tables'!$J$2:$J$20,MATCH(F29,'Code Tables'!$I$2:$I$20,0)),"?") -> Size 1 | H29: cosmo-tee | I29: Red Stripe / 1 | K29: DRAFT | M29: =IF(COUNTIF($A$2:$A$105,A29)>1,"DUPLICATE",IF(ISNA(MATCH(B29,Styles!$A$2:$A$27,0)),"BAD STYLE",IF(ISNA(MATCH(D29,'Code Tables'!$D$2:$D$40,0)),"BAD COLOR",IF(ISNA(MATCH(F29,'Code Tables'!$I$2:$I$20,0)),"BAD SIZE","ok")))) -> ok | O29: =IF(COUNTIFS($B$2:B29,B29,$D$2:D29,D29)=1,1,0) -> 1
A30: =B30&"-"&D30&"-"&F30 -> TP102-RST-02 | B30: TP102 | C30: =IFERROR(INDEX(Styles!$B$2:$B$27,MATCH(B30,Styles!$A$2:$A$27,0)),"?") -> Cosmo Tee | D30: RST | E30: =IFERROR(INDEX('Code Tables'!$E$2:$E$40,MATCH(D30,'Code Tables'!$D$2:$D$40,0)),"?") -> Red Stripe | F30: 02 | G30: =IFERROR(INDEX('Code Tables'!$J$2:$J$20,MATCH(F30,'Code Tables'!$I$2:$I$20,0)),"?") -> Size 2 | H30: cosmo-tee | I30: Red Stripe / 2 | K30: DRAFT | M30: =IF(COUNTIF($A$2:$A$105,A30)>1,"DUPLICATE",IF(ISNA(MATCH(B30,Styles!$A$2:$A$27,0)),"BAD STYLE",IF(ISNA(MATCH(D30,'Code Tables'!$D$2:$D$40,0)),"BAD COLOR",IF(ISNA(MATCH(F30,'Code Tables'!$I$2:$I$20,0)),"BAD SIZE","ok")))) -> ok | O30: =IF(COUNTIFS($B$2:B30,B30,$D$2:D30,D30)=1,1,0) -> 0
A31: =B31&"-"&D31&"-"&F31 -> TP102-RST-03 | B31: TP102 | C31: =IFERROR(INDEX(Styles!$B$2:$B$27,MATCH(B31,Styles!$A$2:$A$27,0)),"?") -> Cosmo Tee | D31: RST | E31: =IFERROR(INDEX('Code Tables'!$E$2:$E$40,MATCH(D31,'Code Tables'!$D$2:$D$40,0)),"?") -> Red Stripe | F31: 03 | G31: =IFERROR(INDEX('Code Tables'!$J$2:$J$20,MATCH(F31,'Code Tables'!$I$2:$I$20,0)),"?") -> Size 3 | H31: cosmo-tee | I31: Red Stripe / 3 | K31: DRAFT | M31: =IF(COUNTIF($A$2:$A$105,A31)>1,"DUPLICATE",IF(ISNA(MATCH(B31,Styles!$A$2:$A$27,0)),"BAD STYLE",IF(ISNA(MATCH(D31,'Code Tables'!$D$2:$D$40,0)),"BAD COLOR",IF(ISNA(MATCH(F31,'Code Tables'!$I$2:$I$20,0)),"BAD SIZE","ok")))) -> ok | O31: =IF(COUNTIFS($B$2:B31,B31,$D$2:D31,D31)=1,1,0) -> 0
A32: =B32&"-"&D32&"-"&F32 -> DR101-BLK-01 | B32: DR101 | C32: =IFERROR(INDEX(Styles!$B$2:$B$27,MATCH(B32,Styles!$A$2:$A$27,0)),"?") -> You Dress | D32: BLK | E32: =IFERROR(INDEX('Code Tables'!$E$2:$E$40,MATCH(D32,'Code Tables'!$D$2:$D$40,0)),"?") -> Black | F32: 01 | G32: =IFERROR(INDEX('Code Tables'!$J$2:$J$20,MATCH(F32,'Code Tables'!$I$2:$I$20,0)),"?") -> Size 1 | H32: you-dress | I32: Black / 1 | J32: CCSS25COD-BLK01 | K32: ACTIVE | L32: SS25 | M32: =IF(COUNTIF($A$2:$A$105,A32)>1,"DUPLICATE",IF(ISNA(MATCH(B32,Styles!$A$2:$A$27,0)),"BAD STYLE",IF(ISNA(MATCH(D32,'Code Tables'!$D$2:$D$40,0)),"BAD COLOR",IF(ISNA(MATCH(F32,'Code Tables'!$I$2:$I$20,0)),"BAD SIZE","ok")))) -> ok | O32: =IF(COUNTIFS($B$2:B32,B32,$D$2:D32,D32)=1,1,0) -> 1
A33: =B33&"-"&D33&"-"&F33 -> DR101-BLK-02 | B33: DR101 | C33: =IFERROR(INDEX(Styles!$B$2:$B$27,MATCH(B33,Styles!$A$2:$A$27,0)),"?") -> You Dress | D33: BLK | E33: =IFERROR(INDEX('Code Tables'!$E$2:$E$40,MATCH(D33,'Code Tables'!$D$2:$D$40,0)),"?") -> Black | F33: 02 | G33: =IFERROR(INDEX('Code Tables'!$J$2:$J$20,MATCH(F33,'Code Tables'!$I$2:$I$20,0)),"?") -> Size 2 | H33: you-dress | I33: Black / 2 | J33: CCSS25COD-BLK02 | K33: ACTIVE | L33: SS25 | M33: =IF(COUNTIF($A$2:$A$105,A33)>1,"DUPLICATE",IF(ISNA(MATCH(B33,Styles!$A$2:$A$27,0)),"BAD STYLE",IF(ISNA(MATCH(D33,'Code Tables'!$D$2:$D$40,0)),"BAD COLOR",IF(ISNA(MATCH(F33,'Code Tables'!$I$2:$I$20,0)),"BAD SIZE","ok")))) -> ok | O33: =IF(COUNTIFS($B$2:B33,B33,$D$2:D33,D33)=1,1,0) -> 0
A34: =B34&"-"&D34&"-"&F34 -> DR101-BLK-03 | B34: DR101 | C34: =IFERROR(INDEX(Styles!$B$2:$B$27,MATCH(B34,Styles!$A$2:$A$27,0)),"?") -> You Dress | D34: BLK | E34: =IFERROR(INDEX('Code Tables'!$E$2:$E$40,MATCH(D34,'Code Tables'!$D$2:$D$40,0)),"?") -> Black | F34: 03 | G34: =IFERROR(INDEX('Code Tables'!$J$2:$J$20,MATCH(F34,'Code Tables'!$I$2:$I$20,0)),"?") -> Size 3 | H34: you-dress | I34: Black / 3 | J34: CCSS25COD-BLK03 | K34: ACTIVE | L34: SS25 | M34: =IF(COUNTIF($A$2:$A$105,A34)>1,"DUPLICATE",IF(ISNA(MATCH(B34,Styles!$A$2:$A$27,0)),"BAD STYLE",IF(ISNA(MATCH(D34,'Code Tables'!$D$2:$D$40,0)),"BAD COLOR",IF(ISNA(MATCH(F34,'Code Tables'!$I$2:$I$20,0)),"BAD SIZE","ok")))) -> ok | O34: =IF(COUNTIFS($B$2:B34,B34,$D$2:D34,D34)=1,1,0) -> 0
A35: =B35&"-"&D35&"-"&F35 -> DR101-WHT-01 | B35: DR101 | C35: =IFERROR(INDEX(Styles!$B$2:$B$27,MATCH(B35,Styles!$A$2:$A$27,0)),"?") -> You Dress | D35: WHT | E35: =IFERROR(INDEX('Code Tables'!$E$2:$E$40,MATCH(D35,'Code Tables'!$D$2:$D$40,0)),"?") -> White | F35: 01 | G35: =IFERROR(INDEX('Code Tables'!$J$2:$J$20,MATCH(F35,'Code Tables'!$I$2:$I$20,0)),"?") -> Size 1 | H35: you-dress | I35: White / 1 | J35: CCSS25COD-WHT01 | K35: ACTIVE | L35: SS25 | M35: =IF(COUNTIF($A$2:$A$105,A35)>1,"DUPLICATE",IF(ISNA(MATCH(B35,Styles!$A$2:$A$27,0)),"BAD STYLE",IF(ISNA(MATCH(D35,'Code Tables'!$D$2:$D$40,0)),"BAD COLOR",IF(ISNA(MATCH(F35,'Code Tables'!$I$2:$I$20,0)),"BAD SIZE","ok")))) -> ok | O35: =IF(COUNTIFS($B$2:B35,B35,$D$2:D35,D35)=1,1,0) -> 1
A36: =B36&"-"&D36&"-"&F36 -> DR101-WHT-02 | B36: DR101 | C36: =IFERROR(INDEX(Styles!$B$2:$B$27,MATCH(B36,Styles!$A$2:$A$27,0)),"?") -> You Dress | D36: WHT | E36: =IFERROR(INDEX('Code Tables'!$E$2:$E$40,MATCH(D36,'Code Tables'!$D$2:$D$40,0)),"?") -> White | F36: 02 | G36: =IFERROR(INDEX('Code Tables'!$J$2:$J$20,MATCH(F36,'Code Tables'!$I$2:$I$20,0)),"?") -> Size 2 | H36: you-dress | I36: White / 2 | J36: CCSS25COD-WHT02 | K36: ACTIVE | L36: SS25 | M36: =IF(COUNTIF($A$2:$A$105,A36)>1,"DUPLICATE",IF(ISNA(MATCH(B36,Styles!$A$2:$A$27,0)),"BAD STYLE",IF(ISNA(MATCH(D36,'Code Tables'!$D$2:$D$40,0)),"BAD COLOR",IF(ISNA(MATCH(F36,'Code Tables'!$I$2:$I$20,0)),"BAD SIZE","ok")))) -> ok | O36: =IF(COUNTIFS($B$2:B36,B36,$D$2:D36,D36)=1,1,0) -> 0
A37: =B37&"-"&D37&"-"&F37 -> DR101-WHT-03 | B37: DR101 | C37: =IFERROR(INDEX(Styles!$B$2:$B$27,MATCH(B37,Styles!$A$2:$A$27,0)),"?") -> You Dress | D37: WHT | E37: =IFERROR(INDEX('Code Tables'!$E$2:$E$40,MATCH(D37,'Code Tables'!$D$2:$D$40,0)),"?") -> White | F37: 03 | G37: =IFERROR(INDEX('Code Tables'!$J$2:$J$20,MATCH(F37,'Code Tables'!$I$2:$I$20,0)),"?") -> Size 3 | H37: you-dress | I37: White / 3 | J37: CCSS25COD-WHT03 | K37: ACTIVE | L37: SS25 | M37: =IF(COUNTIF($A$2:$A$105,A37)>1,"DUPLICATE",IF(ISNA(MATCH(B37,Styles!$A$2:$A$27,0)),"BAD STYLE",IF(ISNA(MATCH(D37,'Code Tables'!$D$2:$D$40,0)),"BAD COLOR",IF(ISNA(MATCH(F37,'Code Tables'!$I$2:$I$20,0)),"BAD SIZE","ok")))) -> ok | O37: =IF(COUNTIFS($B$2:B37,B37,$D$2:D37,D37)=1,1,0) -> 0
A38: =B38&"-"&D38&"-"&F38 -> DR102-WLT-00 | B38: DR102 | C38: =IFERROR(INDEX(Styles!$B$2:$B$27,MATCH(B38,Styles!$A$2:$A$27,0)),"?") -> Story Dress | D38: WLT | E38: =IFERROR(INDEX('Code Tables'!$E$2:$E$40,MATCH(D38,'Code Tables'!$D$2:$D$40,0)),"?") -> Wiltshire (Red) | F38: 00 | G38: =IFERROR(INDEX('Code Tables'!$J$2:$J$20,MATCH(F38,'Code Tables'!$I$2:$I$20,0)),"?") -> Size 0 | H38: story-dress | I38: Red (Wiltshire) / 0 | K38: ACTIVE | M38: =IF(COUNTIF($A$2:$A$105,A38)>1,"DUPLICATE",IF(ISNA(MATCH(B38,Styles!$A$2:$A$27,0)),"BAD STYLE",IF(ISNA(MATCH(D38,'Code Tables'!$D$2:$D$40,0)),"BAD COLOR",IF(ISNA(MATCH(F38,'Code Tables'!$I$2:$I$20,0)),"BAD SIZE","ok")))) -> ok | O38: =IF(COUNTIFS($B$2:B38,B38,$D$2:D38,D38)=1,1,0) -> 1
A39: =B39&"-"&D39&"-"&F39 -> DR102-WLT-01 | B39: DR102 | C39: =IFERROR(INDEX(Styles!$B$2:$B$27,MATCH(B39,Styles!$A$2:$A$27,0)),"?") -> Story Dress | D39: WLT | E39: =IFERROR(INDEX('Code Tables'!$E$2:$E$40,MATCH(D39,'Code Tables'!$D$2:$D$40,0)),"?") -> Wiltshire (Red) | F39: 01 | G39: =IFERROR(INDEX('Code Tables'!$J$2:$J$20,MATCH(F39,'Code Tables'!$I$2:$I$20,0)),"?") -> Size 1 | H39: story-dress | I39: Red (Wiltshire) / 1 | K39: ACTIVE | M39: =IF(COUNTIF($A$2:$A$105,A39)>1,"DUPLICATE",IF(ISNA(MATCH(B39,Styles!$A$2:$A$27,0)),"BAD STYLE",IF(ISNA(MATCH(D39,'Code Tables'!$D$2:$D$40,0)),"BAD COLOR",IF(ISNA(MATCH(F39,'Code Tables'!$I$2:$I$20,0)),"BAD SIZE","ok")))) -> ok | O39: =IF(COUNTIFS($B$2:B39,B39,$D$2:D39,D39)=1,1,0) -> 0
A40: =B40&"-"&D40&"-"&F40 -> DR102-WLT-02 | B40: DR102 | C40: =IFERROR(INDEX(Styles!$B$2:$B$27,MATCH(B40,Styles!$A$2:$A$27,0)),"?") -> Story Dress | D40: WLT | E40: =IFERROR(INDEX('Code Tables'!$E$2:$E$40,MATCH(D40,'Code Tables'!$D$2:$D$40,0)),"?") -> Wiltshire (Red) | F40: 02 | G40: =IFERROR(INDEX('Code Tables'!$J$2:$J$20,MATCH(F40,'Code Tables'!$I$2:$I$20,0)),"?") -> Size 2 | H40: story-dress | I40: Red (Wiltshire) / 2 | K40: ACTIVE | M40: =IF(COUNTIF($A$2:$A$105,A40)>1,"DUPLICATE",IF(ISNA(MATCH(B40,Styles!$A$2:$A$27,0)),"BAD STYLE",IF(ISNA(MATCH(D40,'Code Tables'!$D$2:$D$40,0)),"BAD COLOR",IF(ISNA(MATCH(F40,'Code Tables'!$I$2:$I$20,0)),"BAD SIZE","ok")))) -> ok | O40: =IF(COUNTIFS($B$2:B40,B40,$D$2:D40,D40)=1,1,0) -> 0
...

Sheet Old to New
A1: Old SKU | B1: New SKU | C1: Product | D1: Variant
A2: CCSS25COT-BLK01 | B2: =IFERROR(INDEX(SKUs!$A$2:$A$105,MATCH(A2,SKUs!$J$2:$J$105,0)),"retired") -> TP101-BLK-01 | C2: Cleo Tee | D2: Black / 1
A3: CCSS25COT-BLK02 | B3: =IFERROR(INDEX(SKUs!$A$2:$A$105,MATCH(A3,SKUs!$J$2:$J$105,0)),"retired") -> TP101-BLK-02 | C3: Cleo Tee | D3: Black / 2
A4: CCSS25COT-BLK03 | B4: =IFERROR(INDEX(SKUs!$A$2:$A$105,MATCH(A4,SKUs!$J$2:$J$105,0)),"retired") -> TP101-BLK-03 | C4: Cleo Tee | D4: Black / 3
A5: CCSS25COT-WHT01 | B5: =IFERROR(INDEX(SKUs!$A$2:$A$105,MATCH(A5,SKUs!$J$2:$J$105,0)),"retired") -> TP101-WHT-01 | C5: Cleo Tee | D5: White / 1
A6: CCSS25COT-WHT02 | B6: =IFERROR(INDEX(SKUs!$A$2:$A$105,MATCH(A6,SKUs!$J$2:$J$105,0)),"retired") -> TP101-WHT-02 | C6: Cleo Tee | D6: White / 2
A7: CCSS25COT-WHT03 | B7: =IFERROR(INDEX(SKUs!$A$2:$A$105,MATCH(A7,SKUs!$J$2:$J$105,0)),"retired") -> TP101-WHT-03 | C7: Cleo Tee | D7: White / 3
A8: CCSS26COT-BER01 | B8: =IFERROR(INDEX(SKUs!$A$2:$A$105,MATCH(A8,SKUs!$J$2:$J$105,0)),"retired") -> TP101-BER-01 | C8: Cleo Tee | D8: Blackberry / 1
A9: CCSS26COT-BER02 | B9: =IFERROR(INDEX(SKUs!$A$2:$A$105,MATCH(A9,SKUs!$J$2:$J$105,0)),"retired") -> TP101-BER-02 | C9: Cleo Tee | D9: Blackberry / 2
A10: CCSS26COT-BER03 | B10: =IFERROR(INDEX(SKUs!$A$2:$A$105,MATCH(A10,SKUs!$J$2:$J$105,0)),"retired") -> TP101-BER-03 | C10: Cleo Tee | D10: Blackberry / 3
A11: CCFW25COTNV-SLPS01 | B11: =IFERROR(INDEX(SKUs!$A$2:$A$105,MATCH(A11,SKUs!$J$2:$J$105,0)),"retired") -> TP101-SPS-01 | C11: Cleo Tee | D11: Splash / 1
A12: CCFW25COTNV-SLPS02 | B12: =IFERROR(INDEX(SKUs!$A$2:$A$105,MATCH(A12,SKUs!$J$2:$J$105,0)),"retired") -> TP101-SPS-02 | C12: Cleo Tee | D12: Splash / 2
A13: CCFW25COTNV-SLPS03 | B13: =IFERROR(INDEX(SKUs!$A$2:$A$105,MATCH(A13,SKUs!$J$2:$J$105,0)),"retired") -> TP101-SPS-03 | C13: Cleo Tee | D13: Splash / 3
... A41: CCSS25COT-WHT03-OLD | B41: =IFERROR(INDEX(SKUs!$A$2:$A$105,MATCH(A41,SKUs!$J$2:$J$105,0)),"retired") -> retired | C41: Cleo Tee (archived duplicate) | D41: White / 3

Sheet Code Tables
A1: Cat | B1: Category | C1: Next style | D1: Color | E1: Colorway | F1: Legacy code | G1: SKUs using | I1: Size | J1: Size name | K1: SKUs using
A2: TP | B2: Tops | C2: =A2&(101+COUNTIF(Styles!$C$2:$C$200,A2)) -> TP106 | D2: BLK | E2: Black | G2: =COUNTIF(SKUs!$D$2:$D$105,D2) -> 9 | I2: 00 | J2: Size 0 | K2: =COUNTIF(SKUs!$F$2:$F$105,I2) -> 2
A3: DR | B3: Dresses | C3: =A3&(101+COUNTIF(Styles!$C$2:$C$200,A3)) -> DR106 | D3: WHT | E3: White | G3: =COUNTIF(SKUs!$D$2:$D$105,D3) -> 11 | I3: 01 | J3: Size 1 | K3: =COUNTIF(SKUs!$F$2:$F$105,I3) -> 14
A4: BT | B4: Bottoms | C4: =A4&(101+COUNTIF(Styles!$C$2:$C$200,A4)) -> BT103 | D4: RED | E4: Red | G4: =COUNTIF(SKUs!$D$2:$D$105,D4) -> 4 | I4: 02 | J4: Size 2 | K4: =COUNTIF(SKUs!$F$2:$F$105,I4) -> 14
A5: BG | B5: Bags | C5: =A5&(101+COUNTIF(Styles!$C$2:$C$200,A5)) -> BG107 | D5: BER | E5: Blackberry | G5: =COUNTIF(SKUs!$D$2:$D$105,D5) -> 3 | I5: 03 | J5: Size 3 | K5: =COUNTIF(SKUs!$F$2:$F$105,I5) -> 14
A6: AC | B6: Accessories | C6: =A6&(101+COUNTIF(Styles!$C$2:$C$200,A6)) -> AC105 | D6: SHL | E6: Shell | G6: =COUNTIF(SKUs!$D$2:$D$105,D6) -> 3 | I6: XS | J6: Extra Small | K6: =COUNTIF(SKUs!$F$2:$F$105,I6) -> 5
A7: PT | B7: Parts / Components | C7: =A7&(101+COUNTIF(Styles!$C$2:$C$200,A7)) -> PT103 | D7: SNS | E7: Sunshine | G7: =COUNTIF(SKUs!$D$2:$D$105,D7) -> 3 | I7: SM | J7: Small | K7: =COUNTIF(SKUs!$F$2:$F$105,I7) -> 5
A8: OT | B8: Other | C8: =A8&(101+COUNTIF(Styles!$C$2:$C$200,A8)) -> OT102 | D8: HPK | E8: Hot Pink | G8: =COUNTIF(SKUs!$D$2:$D$105,D8) -> 4 | I8: MD | J8: Medium | K8: =COUNTIF(SKUs!$F$2:$F$105,I8) -> 6
A9: IN | B9: Intimates | C9: =A9&(101+COUNTIF(Styles!$C$2:$C$200,A9)) -> IN102 | D9: SPS | E9: Splash | F9: SLPS | G9: =COUNTIF(SKUs!$D$2:$D$105,D9) -> 3 | I9: LG | J9: Large | K9: =COUNTIF(SKUs!$F$2:$F$105,I9) -> 5
D10: SPL | E10: Splish | G10: =COUNTIF(SKUs!$D$2:$D$105,D10) -> 3 | I10: PT | J10: Petite | K10: =COUNTIF(SKUs!$F$2:$F$105,I10) -> 3
D11: RST | E11: Red Stripe | G11: =COUNTIF(SKUs!$D$2:$D$105,D11) -> 3 | I11: OS | J11: One Size | K11: =COUNTIF(SKUs!$F$2:$F$105,I11) -> 32
D12: WLT | E12: Wiltshire (Red) | G12: =COUNTIF(SKUs!$D$2:$D$105,D12) -> 4 | I12: XL | J12: Extra Large | K12: =COUNTIF(SKUs!$F$2:$F$105,I12) -> 4
D13: BTS | E13: Betsey (Green) | G13: =COUNTIF(SKUs!$D$2:$D$105,D13) -> 4
D14: CHC | E14: Chocolate | F14: CHOC | G14: =COUNTIF(SKUs!$D$2:$D$105,D14) -> 4
D15: SLV | E15: Silver | G15: =COUNTIF(SKUs!$D$2:$D$105,D15) -> 5
D16: GLD | E16: Gold | G16: =COUNTIF(SKUs!$D$2:$D$105,D16) -> 3
D17: MRS | E17: Maraschino | G17: =COUNTIF(SKUs!$D$2:$D$105,D17) -> 3
D18: VRD | E18: Verdant | G18: =COUNTIF(SKUs!$D$2:$D$105,D18) -> 3
D19: CSP | E19: Caspian | G19: =COUNTIF(SKUs!$D$2:$D$105,D19) -> 3
D20: CHP | E20: Champagne | G20: =COUNTIF(SKUs!$D$2:$D$105,D20) -> 1
D21: OLV | E21: Olive | G21: =COUNTIF(SKUs!$D$2:$D$105,D21) -> 1
D22: DBL | E22: Denim Baby Blue | F22: DNM(BLU) | G22: =COUNTIF(SKUs!$D$2:$D$105,D22) -> 1
D23: DPK | E23: Denim Pink | F23: DNM(PNK) | G23: =COUNTIF(SKUs!$D$2:$D$105,D23) -> 1
D24: FLG | E24: Floral / Gold | G24: =COUNTIF(SKUs!$D$2:$D$105,D24) -> 1
D25: DCH | E25: Dark Chocolate | G25: =COUNTIF(SKUs!$D$2:$D$105,D25) -> 4
D26: NAT | E26: Natural | G26: =COUNTIF(SKUs!$D$2:$D$105,D26) -> 2
D27: BDD | E27: Beaded | G27: =COUNTIF(SKUs!$D$2:$D$105,D27) -> 1
D28: NKD | E28: Naked | G28: =COUNTIF(SKUs!$D$2:$D$105,D28) -> 1
D29: STD | E29: Standard | G29: =COUNTIF(SKUs!$D$2:$D$105,D29) -> 1
D30: PNK | E30: Pink | G30: =COUNTIF(SKUs!$D$2:$D$105,D30) -> 10
D31: PRP | E31: Purple | G31: =COUNTIF(SKUs!$D$2:$D$105,D31) -> 5

Sheet To Confirm
A1: # | B1: Item | C1: What I assumed | D1: Why it matters | E1: Your answer
A2: 1 | B2: Cleo Bag as one style | C2: All Cleo Bag colors (Olive, Denim included) sit under BG101. | D2: Mouse tracks five Cleo Bag products. Each maps to a colorway under BG101. | E2: Confirmed Oct 8
A3: 2 | B3: Bean Bag sizes | C3: Petite and Medium are sizes of one style, BG105. | E3: Confirmed Oct 8
A4: 3 | B4: Cleo Tee prints | C4: Neverworns/Splash, Splish, Sunshine etc. are colorways of TP101. | E4: Confirmed Oct 8
A5: 4 | B5: Bateau kits and handle | C5: Bag = body (PT101/PT102) + AC102 handle, same color. Handle fits both sizes and is also sold alone. | E5: Confirmed Oct 8
A6: 5 | B6: Square-only items | C6: Peony and Big Gold Bag are discontinued, so no numbers. | E6: Confirmed Oct 8
A7: 6 | B7: 5to7 Skirt | C7: BT101, sizes XS to XL (XL added to the size list). Product exists, not in Shopify yet. | D7: Is Pink/Purple two colorways (PNK, PRP) or one pink-purple piece? Is Mouse's New Skirt (PO 2362) the same thing? | E7: OPEN
A8: 7 | B8: Cleo Underwear | C8: IN101 in a new category, IN (Intimates). Sizes XS to XL. White and Pink as two colorways. | D8: Underwear doesn't fit the existing categories. Say if you'd rather file it under AC. | E8: OPEN
A9: 8 | B9: Red Bean Bag | C9: BG105-RED-PT, status Live Only. Not in Shopify. | D9: Sold in person only, so it needs a code but no Shopify listing. Is Mouse's Red Bag the same thing? | E9: OPEN
A10: 9 | B10: New Blue (Cleo Tee) | C10: No code yet. | D10: Mouse has a Cleo Tee color called New Blue. Shopify has no such color. It may be Splish, which Shopify describes as vacation blue. Ask Cleo. | E10: OPEN
A11: 10 | B11: Name matches | C11: Ruby Red = RED, Cosmo Stripe Tee = TP102, Hair Tie = AC103, based on the POs and Shopify. | D11: If any of these are different patterns they need their own numbers. | E11: OPEN
A12: 11 | B12: Proposed numbers for products in development | C12: TP103 Cleo Sweater, TP104 Cleo Tank, TP105 Long Sleeve Cleo Tee, DR103 Cleo Tee Dress, DR104 Scoop Neck Dress, DR105 Christmas Dress, BT102 Tutu. | D12: Numbers are cheap but never reused, so strike any you don't want before they go to partners. | E12: OPEN
A13: 12 | B13: Unknown products | C13: Dolce, Silk Flowers and Red Bag have no number. | D13: I don't know what these are. Tell me the category and whether each is a new pattern. | E13: OPEN
A14: 13 | B14: Cachet colorway | C14: FLG (Floral / Gold) is a placeholder code. | D14: Only one variant exists. | E14: OPEN
